Workbook
Name Slicer_Age: #N/A
Name Slicer_age_bins: #N/A
Name Slicer_City: #N/A
Name Slicer_Department: #N/A
Name Slicer_Department1: #N/A
Name Slicer_Department2: #N/A
Name Slicer_Department3: #N/A
Name Slicer_Department4: #N/A
Name Slicer_Department5: #N/A
Name Slicer_Department6: #N/A
Name Slicer_Experience__Years: #N/A
Name Slicer_Experience__Years1: #N/A
Name Slicer_Gender: #N/A
Name Slicer_Gender1: #N/A
Name Slicer_Gender2: #N/A
Name Slicer_Performance: #N/A
Name Slicer_Role: #N/A
Name Slicer_Salary: #N/A
Name Slicer_Salary1: #N/A

Sheet Sheet12
B6: Row Labels | C6: Count of ID
B7: Female | C7: 5
B8: Male | C8: 5
B9: Grand Total | C9: 10
B11: Row Labels | C11: Count of ID
B12: Male | C12: 2
B13: Sales | C13: 2
B14: Grand Total | C14: 2
B22: Row Labels | C22: Sum of Salary
B23: Sales | C23: 108000
B24: Grand Total | C24: 108000
K29: Row Labels | L29: Sum of Age
K30: Female | L30: 28
K31: Grand Total | L31: 28

Sheet Scenario Summary
B2: Scenario Summary
D3: Current Values: | E3: Best Case | F3: Best Case 1 | G3: Best Case 2 | H3: Average Case | I3: Worse Case
E4: Created by 23691A32E1 on 08-06-2026 | F4: Created by 23691A32E1 on 08-06-2026 | G4: Created by 23691A32E1 on 08-06-2026 | H4: Created by 23691A32E1 on 08-06-2026 Modified by 23691A32E1 on 08-06-2026 | I4: Created by 23691A32E1 on 08-06-2026
B5: Changing Cells:
C6: $DE$39 | D6: 100 | E6: 100 | F6: 100 | G6: 100 | H6: 85 | I6: 50
C7: $DE$40 | D7: 95 | E7: 95 | F7: 95 | G7: 95 | H7: 80 | I7: 45
C8: $DE$41 | D8: 95 | E8: 95 | F8: 95 | G8: 95 | H8: 84 | I8: 35
C9: $DE$42 | D9: 122 | E9: 122 | F9: 122 | G9: 122 | H9: 97 | I9: 30
C10: $DE$43 | D10: 175 | E10: 175 | F10: 175 | G10: 175 | H10: 95 | I10: 30
B11: Result Cells:
C12: $DJ$39 | D12: 79 | E12: 79 | F12: 79 | G12: 79 | H12: 79 | I12: 79
C13: $DJ$40 | D13: 80 | E13: 80 | F13: 80 | G13: 80 | H13: 80 | I13: 80
C14: $DJ$41 | D14: 81 | E14: 81 | F14: 81 | G14: 81 | H14: 81 | I14: 81
C15: $DJ$42 | D15: 82 | E15: 82 | F15: 82 | G15: 82 | H15: 82 | I15: 82
C16: $DJ$43 | D16: 83 | E16: 83 | F16: 83 | G16: 83 | H16: 83 | I16: 83
C17: $DJ$44 | D17: 84 | E17: 84 | F17: 84 | G17: 84 | H17: 84 | I17: 84
B18: Notes: Current Values column represents values of changing cells at
B19: time Scenario Summary Report was created. Changing cells for each
B20: scenario are highlighted in gray.

Sheet telecom_churn
A1: Churn | B1: AccountWeeks | C1: GENDER | D1: ContractRenewal | E1: DataPlan | F1: DataUsage | G1: CustServCalls | H1: DayMins | I1: DayCalls | J1: MonthlyCharge | K1: OverageFee | L1: RoamMins | M1: SQRT | N1: ROUND | O1: MIN | P1: MAX | Q1: AVERAGE | R1: SUM | S1: MEDAIN | T1: RANK | U1: LEFT | V1: Right | W1: Length | X1: Date | Y1: Year | Z1: Month | AA1: DAY | AB1: WEEKDAYS | AC1: EOMONTH | AD1: NETWORK DAYS | AF1: TEXT FUNCTIONS | AP1: CONDITIONAL FORMATTING | BC1: STATISTICAL ANALYSIS | BR1: correlation
A2: 0 | B2: 128 | C2: Male | D2: 1 | E2: 1 | F2: 2.7 | G2: 1 | H2: 265.1 | I2: 110 | J2: 89 | K2: 9.87 | L2: 10 | M2: =SQRT(B2) -> 11.313708 | N2: =O3 -> 123 | O2: =MIN(Table22[[#This Row],[DayMins]:[DayCalls]]) -> 110 | P2: =MAX(H2,I2) -> 265.1 | Q2: =AVERAGE(H2,I2) -> 187.55 | R2: =SUM(H2,I2) -> 375.1 | S2: =MEDIAN(D2,G2) -> 1 | U2: =V4 -> le | V2: =RIGHT(C2,2) -> le | W2: =LEN(C2) -> 4 | X2: 46113 | Y2: =YEAR(X2) -> 2026 | Z2: =MONTH(X2) -> 4 | AA2: =DAY(X2) -> 1 | AB2: =WEEKDAY(X2) -> 4 | AC2: =EOMONTH(X2,2) -> 46203 | AD2: =NETWORKDAYS(X2,AC2) -> 65 | AF2: INPUT | AG2: INPUT2 | AH2: FIND | AI2: INPUT3 | AJ2: REPLACE | AK2: SUBSTITUTE | AL2: MID | AM2: SEARCH | AN2: CONCAT | AP2: ID | AQ2: Name | AR2: Age | AS2: Gender | AT2: Employee Role | AU2: Salary | AV2: Department | AW2: Experience (Years) | AX2: City | BC2: Student ID | BD2: Name | BE2: Age | BF2: Gender | BG2: City | BH2: Math Marks | BI2: Science Marks | BJ2: English Marks | BK2: Attendance (%) | BM2: Anova: Two-Factor With Replication | BS2: Math Marks | BT2: Science Marks | BU2: English Marks | DA2: Row Labels | DB2: Sum of Age
A3: 0 | B3: 107 | C3: Male | D3: 1 | E3: 1 | F3: 3.7 | G3: 1 | H3: 161.6 | I3: 123 | J3: 82 | K3: 9.78 | L3: 13.7 | M3: =SQRT(B3) -> 10.34408 | N3: =ROUND(Table1[[#This Row],[SQRT]],2) -> 10.34 | O3: =MIN(H3,I3) -> 123 | P3: =MAX(H3,I3) -> 161.6 | Q3: =AVERAGE(H3,I3) -> 142.3 | R3: =SUM(H3,I3) -> 284.6 | S3: =MEDIAN(D3,G3) -> 1 | T3: =RANK(B3,B:B) -> #N/A | U3: =LEFT(C3,1) -> M | V3: =RIGHT(C3,2) -> le | W3: =LEN(C3) -> 4 | X3: 46114 | Y3: =YEAR(X3) -> 2026 | Z3: =MONTH(X3) -> 4 | AA3: =DAY(X3) -> 2 | AB3: =WEEKDAY(X3) -> 5 | AC3: =EOMONTH(X3,4) -> 46265 | AD3: =NETWORKDAYS(X3,AC3) -> 108 | AF3: A | AG3: APPLE | AH3: =FIND(AF3,AG3) -> 1 | AI3: ABC-2026-011 | AJ3: =REPLACE(AI3,1,3,"EFG") -> EFG-2026-011 | AK3: =SUBSTITUTE(AI3,"ABC","ZZZ") -> ZZZ-2026-011 | AL3: =MID(AG3,2,3) -> PPL | AM3: =SEARCH("L",AG3,1) -> 4 | AN3: =_xlfn.CONCAT(AG3,AG9) -> APPLE | AP3: 1 | AQ3: Rahul Kumar | AR3: 25 | AS3: Male | AT3: Data Analyst | AU3: 35000 | AV3: IT | AW3: 2 | AX3: Hyderabad | BC3: 101 | BD3: Rahul | BE3: 18 | BF3: Male | BG3: Guntur | BH3: 78 | BI3: 82 | BJ3: 75 | BK3: 92 | BR3: Math Marks | BS3: 1 | CB3: ID | CC3: Name | CD3: Gender | CE3: City | CF3: Department | CG3: Age | CH3: Salary | CI3: Performance | CJ3: age bins | CL3: Row Labels | CM3: Sum of Salary | DA3: Finance | DB3: 56
A4: 0 | B4: 137 | C4: Male | D4: 1 | E4: 0 | F4: 0 | G4: 0 | H4: 243.4 | I4: 114 | J4: 52 | K4: 6.06 | L4: 12.2 | M4: =SQRT(B4) -> 11.7047 | N4: =ROUND(Table1[[#This Row],[SQRT]],2) -> 11.7 | O4: =MIN(H4,I4) -> 114 | P4: =MAX(H4,I4) -> 243.4 | Q4: =AVERAGE(H4,I4) -> 178.7 | R4: =SUM(H4,I4) -> 357.4 | S4: =MEDIAN(D4,G4) -> 0.5 | T4: =RANK(B4,B:B) -> #N/A | U4: =LEFT(C4,1) -> M | V4: =RIGHT(C4,2) -> le | W4: =LEN(C4) -> 4 | X4: 46115 | Y4: =YEAR(X4) -> 2026 | Z4: =MONTH(X4) -> 4 | AA4: =DAY(X4) -> 3 | AB4: =WEEKDAY(X4) -> 6 | AC4: =EOMONTH(X4,4) -> 46265 | AD4: =NETWORKDAYS(X4,AC4) -> 107 | AF4: P | AG4: APPLE | AH4: =FIND(AF4,AG4) -> 2 | AJ4: =REPLACE(AI3,5,4,"2027") -> ABC-2027-011 | AK4: =SUBSTITUTE(AI3,"011","022") -> ABC-2026-022 | AL4: =MID(AG4,1,5) -> APPLE | AM4: =SEARCH("E",AG4,1) -> 5 | AP4: 2 | AQ4: Priya Singh | AR4: 28 | AS4: Female | AT4: HR Executive | AU4: 40000 | AV4: HR | AW4: 4 | AX4: Chennai | BC4: 102 | BD4: Priya | BE4: 19 | BF4: Female | BG4: Vijayawada | BH4: 85 | BI4: 88 | BJ4: 90 | BK4: 95 | BM4: SUMMARY | BN4: Science Marks | BO4: English Marks | BP4: Total | BR4: Science Marks | BS4: 0.98312431 | BT4: 1 | CB4: 1 | CC4: Rahul | CD4: Male | CE4: Hyderabad | CF4: IT | CG4: 25 | CH4: 45000 | CI4: Good | CJ4: =IF(CG4<20,"Below 20",IF(CG4<=25,"20-25",IF(CG4<=30,"26-30",IF(CG4<=35,"31-35","Above 35")))) -> 20-25 | CL4: Male | CM4: 263000 | DA4: Female | DB4: 26
A5: 0 | B5: 84 | C5: Male | D5: 0 | E5: 0 | F5: 0 | G5: 2 | H5: 299.4 | I5: 71 | J5: 57 | K5: 3.1 | L5: 6.6 | M5: =SQRT(B5) -> 9.1651514 | N5: =ROUND(Table1[[#This Row],[SQRT]],2) -> 9.17 | O5: =MIN(H5,I5) -> 71 | P5: =MAX(H5,I5) -> 299.4 | Q5: =AVERAGE(H5,I5) -> 185.2 | R5: =SUM(H5,I5) -> 370.4 | S5: =MEDIAN(D5,G5) -> 1 | T5: =RANK(B5,B:B) -> #N/A | U5: =LEFT(C5,1) -> M | V5: =RIGHT(C5,2) -> le | W5: =LEN(C5) -> 4 | X5: 46116 | Y5: =YEAR(X5) -> 2026 | Z5: =MONTH(X5) -> 4 | AA5: =DAY(X5) -> 4 | AB5: =WEEKDAY(X5) -> 7 | AC5: =EOMONTH(X5,4) -> 46265 | AD5: =NETWORKDAYS(X5,AC5) -> 106 | AF5: P | AG5: APPLE | AH5: =FIND(AF5,AG5) -> 2 | AL5: =MID(AG5,3,5) -> PLE | AP5: 3 | AQ5: Arjun Reddy | AR5: 30 | AS5: Male | AT5: Software Engineer | AU5: 55000 | AV5: IT | AW5: 6 | AX5: Bengaluru | BC5: 103 | BD5: Kiran | BE5: 18 | BF5: Male | BG5: Tenali | BH5: 65 | BI5: 70 | BJ5: 68 | BK5: 85 | BM5: 78 | BR5: English Marks | BS5: 0.97810919 | BT5: 0.96831539 | BU5: 1 | CB5: 2 | CC5: Priya | CD5: Female | CE5: Chennai | CF5: HR | CG5: 28 | CH5: 40000 | CI5: Excellent | CJ5: =IF(CG5<20,"Below 20",IF(CG5<=25,"20-25",IF(CG5<=30,"26-30",IF(CG5<=35,"31-35","Above 35")))) -> 26-30 | CL5: Grand Total | CM5: 263000 | DA5: Male | DB5: 30
A6: 0 | B6: 75 | C6: Male | D6: 0 | E6: 0 | F6: 0 | G6: 3 | H6: 166.7 | I6: 113 | J6: 41 | K6: 7.42 | L6: 10.1 | M6: =SQRT(B6) -> 8.660254 | N6: =ROUND(Table1[[#This Row],[SQRT]],2) -> 8.66 | O6: =MIN(H6,I6) -> 113 | P6: =MAX(H6,I6) -> 166.7 | Q6: =AVERAGE(H6,I6) -> 139.85 | R6: =SUM(H6,I6) -> 279.7 | S6: =MEDIAN(D6,G6) -> 1.5 | T6: =RANK(B6,B:B) -> #N/A | U6: =LEFT(C6,1) -> M | V6: =RIGHT(C6,2) -> le | W6: =LEN(C6) -> 4 | X6: 46117 | Y6: =YEAR(X6) -> 2026 | Z6: =MONTH(X6) -> 4 | AA6: =DAY(X6) -> 5 | AB6: =WEEKDAY(X6) -> 1 | AC6: =EOMONTH(X6,4) -> 46265 | AD6: =NETWORKDAYS(X6,AC6) -> 106 | AF6: L | AG6: APPLE | AH6: =FIND(AF6,AG6) -> 4 | AP6: 4 | AQ6: Sneha Patel | AR6: 27 | AS6: Female | AT6: Accountant | AU6: 42000 | AV6: Finance | AW6: 3 | AX6: Mumbai | BC6: 104 | BD6: Sneha | BE6: 20 | BF6: Female | BG6: Guntur | BH6: 92 | BI6: 95 | BJ6: 91 | BK6: 98 | BM6: Count | BN6: 10 | BO6: 10 | BP6: 20 | CB6: 3 | CC6: Arjun | CD6: Male | CE6: Bangalore | CF6: Finance | CG6: 30 | CH6: 50000 | CI6: Average | CJ6: =IF(CG6<20,"Below 20",IF(CG6<=25,"20-25",IF(CG6<=30,"26-30",IF(CG6<=35,"31-35","Above 35")))) -> 26-30 | DA6: HR | DB6: 81
A7: 0 | B7: 118 | C7: Male | D7: 0 | E7: 0 | F7: 0 | G7: 0 | H7: 223.4 | I7: 98 | J7: 57 | K7: 11.03 | L7: 6.3 | M7: =SQRT(B7) -> 10.86278 | N7: =ROUND(Table1[[#This Row],[SQRT]],2) -> 10.86 | O7: =MIN(H7,I7) -> 98 | P7: =MAX(H7,I7) -> 223.4 | Q7: =AVERAGE(H7,I7) -> 160.7 | R7: =SUM(H7,I7) -> 321.4 | S7: =MEDIAN(D7,G7) -> 0 | T7: =RANK(B7,B:B) -> #N/A | U7: =LEFT(C7,1) -> M | V7: =RIGHT(C7,2) -> le | W7: =LEN(C7) -> 4 | X7: 46118 | Y7: =YEAR(X7) -> 2026 | Z7: =MONTH(X7) -> 4 | AA7: =DAY(X7) -> 6 | AB7: =WEEKDAY(X7) -> 2 | AC7: =EOMONTH(X7,4) -> 46265 | AD7: =NETWORKDAYS(X7,AC7) -> 106 | AF7: E | AG7: APPLE | AH7: =FIND(AF7,AG7) -> 5 | AI7: MANGO | AP7: 5 | AQ7: Kiran Rao | AR7: 35 | AS7: Male | AT7: Project Manager | AU7: 75000 | AV7: Operations | AW7: 10 | AX7: Pune | BC7: 105 | BD7: Arjun | BE7: 19 | BF7: Male | BG7: Ongole | BH7: 74 | BI7: 78 | BJ7: 72 | BK7: 89 | BM7: Sum | BN7: 823 | BO7: 793 | BP7: 1616 | CB7: 4 | CC7: Sneha | CD7: Female | CE7: Mumbai | CF7: IT | CG7: 27 | CH7: 48000 | CI7: Good | CJ7: =IF(CG7<20,"Below 20",IF(CG7<=25,"20-25",IF(CG7<=30,"26-30",IF(CG7<=35,"31-35","Above 35")))) -> 26-30 | DA7: Female | DB7: 81
A8: 0 | B8: 121 | C8: Male | D8: 1 | E8: 1 | F8: 2.03 | G8: 3 | H8: 218.2 | I8: 88 | J8: 87.3 | K8: 17.43 | L8: 7.5 | M8: =SQRT(B8) -> 11 | N8: =ROUND(Table1[[#This Row],[SQRT]],2) -> 11 | O8: =MIN(H8,I8) -> 88 | P8: =MAX(H8,I8) -> 218.2 | Q8: =AVERAGE(H8,I8) -> 153.1 | R8: =SUM(H8,I8) -> 306.2 | S8: =MEDIAN(D8,G8) -> 2 | T8: =RANK(B8,B:B) -> #N/A | U8: =LEFT(C8,1) -> M | V8: =RIGHT(C8,2) -> le | W8: =LEN(C8) -> 4 | X8: 46119 | Y8: =YEAR(X8) -> 2026 | Z8: =MONTH(X8) -> 4 | AA8: =DAY(X8) -> 7 | AB8: =WEEKDAY(X8) -> 3 | AC8: =EOMONTH(X8,4) -> 46265 | AD8: =NETWORKDAYS(X8,AC8) -> 105 | AP8: 6 | AQ8: Anjali Devi | AR8: 24 | AS8: Female | AT8: Marketing Executive | AU8: 32000 | AV8: Marketing | AW8: 1 | AX8: Delhi | BC8: 106 | BD8: Divya | BE8: 18 | BF8: Female | BG8: Tenali | BH8: 88 | BI8: 84 | BJ8: 86 | BK8: 94 | BM8: Average | BN8: 82.3 | BO8: 79.3 | BP8: 80.8 | BR8: CO-VARIANCE | CB8: 5 | CC8: Kiran | CD8: Male | CE8: Hyderabad | CF8: Sales | CG8: 35 | CH8: 55000 | CI8: Excellent | CJ8: =IF(CG8<20,"Below 20",IF(CG8<=25,"20-25",IF(CG8<=30,"26-30",IF(CG8<=35,"31-35","Above 35")))) -> 31-35 | CL8: Row Labels | CM8: Sum of Salary | DA8: IT | DB8: 83
A9: 0 | B9: 147 | C9: Male | D9: 0 | E9: 0 | F9: 0 | G9: 0 | H9: 157 | I9: 79 | J9: 36 | K9: 5.16 | L9: 7.1 | M9: =SQRT(B9) -> 12.124356 | N9: =ROUND(Table1[[#This Row],[SQRT]],2) -> 12.12 | O9: =MIN(H9,I9) -> 79 | P9: =MAX(H9,I9) -> 157 | Q9: =AVERAGE(H9,I9) -> 118 | R9: =SUM(H9,I9) -> 236 | S9: =MEDIAN(D9,G9) -> 0 | T9: =RANK(B9,B:B) -> #N/A | U9: =LEFT(C9,1) -> M | V9: =RIGHT(C9,2) -> le | W9: =LEN(C9) -> 4 | X9: 46120 | Y9: =YEAR(X9) -> 2026 | Z9: =MONTH(X9) -> 4 | AA9: =DAY(X9) -> 8 | AB9: =WEEKDAY(X9) -> 4 | AC9: =EOMONTH(X9,4) -> 46265 | AD9: =NETWORKDAYS(X9,AC9) -> 104 | AP9: 7 | AQ9: Vikas Sharma | AR9: 32 | AS9: Male | AT9: Team Lead | AU9: 68000 | AV9: IT | AW9: 8 | AX9: Kolkata | BC9: 107 | BD9: Ramesh | BE9: 20 | BF9: Male | BG9: Vijayawada | BH9: 55 | BI9: 60 | BJ9: 58 | BK9: 80 | BM9: Variance | BN9: 142.01111 | BO9: 149.56667 | BP9: 140.48421 | BS9: Column 1 | BT9: Column 2 | BU9: Column 3 | CB9: 6 | CC9: Divya | CD9: Female | CE9: Chennai | CF9: HR | CG9: 29 | CH9: 42000 | CI9: Good | CJ9: =IF(CG9<20,"Below 20",IF(CG9<=25,"20-25",IF(CG9<=30,"26-30",IF(CG9<=35,"31-35","Above 35")))) -> 26-30 | CL9: Finance | CM9: 97000 | DA9: Female | DB9: 27
A10: 0 | B10: 117 | C10: Male | D10: 1 | E10: 0 | F10: 0.19 | G10: 1 | H10: 184.5 | I10: 97 | J10: 63.9 | K10: 17.58 | L10: 8.7 | M10: =SQRT(B10) -> 10.816654 | N10: =ROUND(Table1[[#This Row],[SQRT]],2) -> 10.82 | O10: =MIN(H10,I10) -> 97 | P10: =MAX(H10,I10) -> 184.5 | Q10: =AVERAGE(H10,I10) -> 140.75 | R10: =SUM(H10,I10) -> 281.5 | S10: =MEDIAN(D10,G10) -> 1 | T10: =RANK(B10,B:B) -> #N/A | U10: =LEFT(C10,1) -> M | V10: =RIGHT(C10,2) -> le | W10: =LEN(C10) -> 4 | X10: 46121 | Y10: =YEAR(X10) -> 2026 | Z10: =MONTH(X10) -> 4 | AA10: =DAY(X10) -> 9 | AB10: =WEEKDAY(X10) -> 5 | AC10: =EOMONTH(X10,4) -> 46265 | AD10: =NETWORKDAYS(X10,AC10) -> 103 | AP10: 8 | AQ10: Meera Nair | AR10: 29 | AS10: Female | AT10: Business Analyst | AU10: 50000 | AV10: Business | AW10: 5 | AX10: Kochi | BC10: 108 | BD10: Anitha | BE10: 19 | BF10: Female | BG10: Guntur | BH10: 90 | BI10: 93 | BJ10: 89 | BK10: 97 | BR10: Column 1 | BS10: =VARP(telecom_churn!$BH$3:$BH$12) -> 154.05 | CB10: 7 | CC10: Rohit | CD10: Male | CE10: Bangalore | CF10: IT | CG10: 31 | CH10: 60000 | CI10: Excellent | CJ10: =IF(CG10<20,"Below 20",IF(CG10<=25,"20-25",IF(CG10<=30,"26-30",IF(CG10<=35,"31-35","Above 35")))) -> 31-35 | CL10: HR | CM10: 121000 | DA10: Male | DB10: 56
A11: 0 | B11: 141 | C11: Female | D11: 0 | E11: 1 | F11: 3.02 | G11: 0 | H11: 258.6 | I11: 84 | J11: 93.2 | K11: 11.1 | L11: 11.2 | M11: =SQRT(B11) -> 11.874342 | N11: =ROUND(Table1[[#This Row],[SQRT]],2) -> 11.87 | O11: =MIN(H11,I11) -> 84 | P11: =MAX(H11,I11) -> 258.6 | Q11: =AVERAGE(H11,I11) -> 171.3 | R11: =SUM(H11,I11) -> 342.6 | S11: =MEDIAN(D11,G11) -> 0 | T11: =RANK(B11,B:B) -> #N/A | U11: =LEFT(C11,1) -> F | V11: =RIGHT(C11,2) -> le | W11: =LEN(C11) -> 6 | X11: 46122 | Y11: =YEAR(X11) -> 2026 | Z11: =MONTH(X11) -> 4 | AA11: =DAY(X11) -> 10 | AB11: =WEEKDAY(X11) -> 6 | AC11: =EOMONTH(X11,4) -> 46265 | AD11: =NETWORKDAYS(X11,AC11) -> 102 | AP11: 9 | AQ11: Ramesh Gupta | AR11: 40 | AS11: Male | AT11: General Manager | AU11: 90000 | AV11: Management | AW11: 15 | AX11: Jaipur | BC11: 109 | BD11: Suresh | BE11: 18 | BF11: Male | BG11: Ongole | BH11: 72 | BI11: 75 | BJ11: 70 | BK11: 88 | BM11: Total | BR11: Column 2 | BS11: 137.95 | BT11: =VARP(telecom_churn!$BI$3:$BI$12) -> 127.81 | CB11: 8 | CC11: Anjali | CD11: Female | CE11: Mumbai | CF11: Finance | CG11: 26 | CH11: 47000 | CI11: Average | CJ11: =IF(CG11<20,"Below 20",IF(CG11<=25,"20-25",IF(CG11<=30,"26-30",IF(CG11<=35,"31-35","Above 35")))) -> 26-30 | CL11: IT | CM11: 153000 | DA11: Sales | DB11: 68
A12: 1 | B12: 65 | C12: Female | D12: 1 | E12: 0 | F12: 0.29 | G12: 4 | H12: 129.1 | I12: 137 | J12: 44.9 | K12: 11.43 | L12: 12.7 | M12: =SQRT(B12) -> 8.0622577 | N12: =ROUND(Table1[[#This Row],[SQRT]],2) -> 8.06 | O12: =MIN(H12,I12) -> 129.1 | P12: =MAX(H12,I12) -> 137 | Q12: =AVERAGE(H12,I12) -> 133.05 | R12: =SUM(H12,I12) -> 266.1 | S12: =MEDIAN(D12,G12) -> 2.5 | T12: =RANK(B12,B:B) -> #N/A | U12: =LEFT(C12,1) -> F | V12: =RIGHT(C12,2) -> le | W12: =LEN(C12) -> 6 | X12: 46123 | Y12: =YEAR(X12) -> 2026 | Z12: =MONTH(X12) -> 4 | AA12: =DAY(X12) -> 11 | AB12: =WEEKDAY(X12) -> 7 | AC12: =EOMONTH(X12,4) -> 46265 | AD12: =NETWORKDAYS(X12,AC12) -> 101 | AF12: MATHEMATICAL FUNCTIONS | AP12: 10 | AQ12: Pooja Verma | AR12: 26 | AS12: Female | AT12: UI/UX Designer | AU12: 45000 | AV12: Design | AW12: 3 | AX12: Noida | BC12: 110 | BD12: Kavya | BE12: 20 | BF12: Female | BG12: Vijayawada | BH12: 96 | BI12: 98 | BJ12: 94 | BK12: 99 | BM12: Count | BN12: 10 | BO12: 10 | BR12: Column 3 | BS12: 140.85 | BT12: 127.01 | BU12: =VARP(telecom_churn!$BJ$3:$BJ$12) -> 134.61 | CB12: 9 | CC12: Varun | CD12: Male | CE12: Hyderabad | CF12: Sales | CG12: 33 | CH12: 53000 | CI12: Good | CJ12: =IF(CG12<20,"Below 20",IF(CG12<=25,"20-25",IF(CG12<=30,"26-30",IF(CG12<=35,"31-35","Above 35")))) -> 31-35 | CL12: Sales | CM12: 108000 | DA12: Male | DB12: 68
A13: 0 | B13: 74 | C13: Female | D13: 1 | E13: 0 | F13: 0.34 | G13: 0 | H13: 187.7 | I13: 127 | J13: 49.4 | K13: 8.17 | L13: 9.1 | M13: =SQRT(B13) -> 8.6023253 | N13: =ROUND(Table1[[#This Row],[SQRT]],2) -> 8.6 | O13: =MIN(H13,I13) -> 127 | P13: =MAX(H13,I13) -> 187.7 | Q13: =AVERAGE(H13,I13) -> 157.35 | R13: =SUM(H13,I13) -> 314.7 | S13: =MEDIAN(D13,G13) -> 0.5 | T13: =RANK(B13,B:B) -> #N/A | U13: =LEFT(C13,1) -> F | V13: =RIGHT(C13,2) -> le | W13: =LEN(C13) -> 6 | X13: 46124 | Y13: =YEAR(X13) -> 2026 | Z13: =MONTH(X13) -> 4 | AA13: =DAY(X13) -> 12 | AB13: =WEEKDAY(X13) -> 1 | AC13: =EOMONTH(X13,4) -> 46265 | AD13: =NETWORKDAYS(X13,AC13) -> 101 | AP13: 11 | AQ13: Sunil Kumar | AR13: 31 | AS13: Male | AT13: Network Engineer | AU13: 52000 | AV13: IT | AW13: 7 | AX13: Vijayawada | BA13: 30 | BM13: Sum | BN13: 823 | BO13: 793 | CB13: 10 | CC13: Pooja | CD13: Female | CE13: Bangalore | CF13: HR | CG13: 24 | CH13: 39000 | CI13: Excellent | CJ13: =IF(CG13<20,"Below 20",IF(CG13<=25,"20-25",IF(CG13<=30,"26-30",IF(CG13<=35,"31-35","Above 35")))) -> 20-25 | CL13: Grand Total | CM13: 479000 | DA13: Grand Total | DB13: 288
A14: 0 | B14: 168 | C14: Female | D14: 1 | E14: 0 | F14: 0 | G14: 1 | H14: 128.8 | I14: 96 | J14: 31 | K14: 5.25 | L14: 11.2 | M14: =SQRT(B14) -> 12.961481 | N14: =ROUND(Table1[[#This Row],[SQRT]],2) -> 12.96 | O14: =MIN(H14,I14) -> 96 | P14: =MAX(H14,I14) -> 128.8 | Q14: =AVERAGE(H14,I14) -> 112.4 | R14: =SUM(H14,I14) -> 224.8 | S14: =MEDIAN(D14,G14) -> 1 | T14: =RANK(B14,B:B) -> #N/A | U14: =LEFT(C14,1) -> F | V14: =RIGHT(C14,2) -> le | W14: =LEN(C14) -> 6 | X14: 46125 | Y14: =YEAR(X14) -> 2026 | Z14: =MONTH(X14) -> 4 | AA14: =DAY(X14) -> 13 | AB14: =WEEKDAY(X14) -> 2 | AC14: =EOMONTH(X14,4) -> 46265 | AD14: =NETWORKDAYS(X14,AC14) -> 101 | AF14: PRODUCT | AG14: MOD | AH14: FACT | AI14: ROUND | AJ14: ROUNDDOWN | AK14: ROUNDUP | AP14: 12 | AQ14: Kavya Reddy | AR14: 23 | AS14: Female | AT14: Content Writer | AU14: 28000 | AV14: Marketing | AW14: 1 | AX14: Guntur | BD14: Anova: Single Factor | BM14: Average | BN14: 82.3 | BO14: 79.3
A15: 0 | B15: 95 | C15: Female | D15: 1 | E15: 0 | F15: 0.44 | G15: 3 | H15: 156.6 | I15: 88 | J15: 52.4 | K15: 12.38 | L15: 12.3 | M15: =SQRT(B15) -> 9.7467943 | N15: =ROUND(Table1[[#This Row],[SQRT]],2) -> 9.75 | O15: =MIN(H15,I15) -> 88 | P15: =MAX(H15,I15) -> 156.6 | Q15: =AVERAGE(H15,I15) -> 122.3 | R15: =SUM(H15,I15) -> 244.6 | S15: =MEDIAN(D15,G15) -> 2 | T15: =RANK(B15,B:B) -> #N/A | U15: =LEFT(C15,1) -> F | V15: =RIGHT(C15,2) -> le | W15: =LEN(C15) -> 6 | X15: 46126 | Y15: =YEAR(X15) -> 2026 | Z15: =MONTH(X15) -> 4 | AA15: =DAY(X15) -> 14 | AB15: =WEEKDAY(X15) -> 3 | AC15: =EOMONTH(X15,4) -> 46265 | AD15: =NETWORKDAYS(X15,AC15) -> 100 | AF15: =PRODUCT(3,9) -> 27 | AG15: =MOD(77,3) -> 2 | AH15: =FACT(6) -> 720 | AI15: =ROUND(SQRT(45),2) -> 6.71 | AJ15: =ROUNDDOWN(SQRT(38),2) -> 6.16 | AK15: =ROUNDUP(SQRT(68),2) -> 8.25 | AP15: 13 | AQ15: Manoj Sharma | AR15: 38 | AS15: Male | AT15: Senior Developer | AU15: 80000 | AV15: IT | AW15: 12 | AX15: Hyderabad | BM15: Variance | BN15: 142.01111 | BO15: 149.56667 | CC15: Row Labels | CD15: Sum of Salary | DD15: Row Labels | DE15: Count of ID
A16: 0 | B16: 62 | C16: Female | D16: 1 | E16: 0 | F16: 0 | G16: 4 | H16: 120.7 | I16: 70 | J16: 47 | K16: 15.36 | L16: 13.1 | M16: =SQRT(B16) -> 7.8740079 | N16: =ROUND(Table1[[#This Row],[SQRT]],2) -> 7.87 | O16: =MIN(H16,I16) -> 70 | P16: =MAX(H16,I16) -> 120.7 | Q16: =AVERAGE(H16,I16) -> 95.35 | R16: =SUM(H16,I16) -> 190.7 | S16: =MEDIAN(D16,G16) -> 2.5 | T16: =RANK(B16,B:B) -> #N/A | U16: =LEFT(C16,1) -> F | V16: =RIGHT(C16,2) -> le | W16: =LEN(C16) -> 6 | X16: 46127 | Y16: =YEAR(X16) -> 2026 | Z16: =MONTH(X16) -> 4 | AA16: =DAY(X16) -> 15 | AB16: =WEEKDAY(X16) -> 4 | AC16: =EOMONTH(X16,4) -> 46265 | AD16: =NETWORKDAYS(X16,AC16) -> 99 | AF16: =PRODUCT(10,5) -> 50 | AG16: =MOD(100,5) -> 0 | AH16: =FACT(10) -> 3628800 | AI16: =ROUND(SQRT(26),2) -> 5.1 | AJ16: =ROUNDDOWN(SQRT(42),2) -> 6.48 | AK16: =ROUNDUP(SQRT(28),2) -> 5.3 | AP16: 14 | AQ16: Deepika Das | AR16: 29 | AS16: Female | AT16: Recruiter | AU16: 39000 | AV16: HR | AW16: 5 | AX16: Bhubaneswar | BD16: SUMMARY | CC16: Average | CD16: 97000 | CM16: Row Labels | CN16: Sum of Age | CO16: Sum of Salary | DD16: Bangalore | DE16: 3
A17: 1 | B17: 161 | C17: Female | D17: 1 | E17: 0 | F17: 0 | G17: 4 | H17: 332.9 | I17: 67 | J17: 84 | K17: 15.89 | L17: 5.4 | M17: =SQRT(B17) -> 12.688578 | N17: =ROUND(Table1[[#This Row],[SQRT]],2) -> 12.69 | O17: =MIN(H17,I17) -> 67 | P17: =MAX(H17,I17) -> 332.9 | Q17: =AVERAGE(H17,I17) -> 199.95 | R17: =SUM(H17,I17) -> 399.9 | S17: =MEDIAN(D17,G17) -> 2.5 | T17: =RANK(B17,B:B) -> #N/A | U17: =LEFT(C17,1) -> F | V17: =RIGHT(C17,2) -> le | W17: =LEN(C17) -> 6 | X17: 46128 | Y17: =YEAR(X17) -> 2026 | Z17: =MONTH(X17) -> 4 | AA17: =DAY(X17) -> 16 | AB17: =WEEKDAY(X17) -> 5 | AC17: =EOMONTH(X17,4) -> 46265 | AD17: =NETWORKDAYS(X17,AC17) -> 98 | AP17: 15 | AQ17: Akash Jain | AR17: 27 | AS17: Male | AT17: Sales Executive | AU17: 36000 | AV17: Sales | AW17: 3 | AX17: Indore | BD17: Groups | BE17: Count | BF17: Sum | BG17: Average | BH17: Variance | CC17: Excellent | CD17: 194000 | CM17: 20-25 | CN17: 49 | CO17: 84000 | DD17: Chennai | DE17: 2
A18: 0 | B18: 85 | C18: Female | D18: 1 | E18: 1 | F18: 3.73 | G18: 1 | H18: 196.4 | I18: 139 | J18: 95.3 | K18: 14.05 | L18: 13.8 | M18: =SQRT(B18) -> 9.2195445 | N18: =ROUND(Table1[[#This Row],[SQRT]],2) -> 9.22 | O18: =MIN(H18,I18) -> 139 | P18: =MAX(H18,I18) -> 196.4 | Q18: =AVERAGE(H18,I18) -> 167.7 | R18: =SUM(H18,I18) -> 335.4 | S18: =MEDIAN(D18,G18) -> 1 | T18: =RANK(B18,B:B) -> #N/A | U18: =LEFT(C18,1) -> F | V18: =RIGHT(C18,2) -> le | W18: =LEN(C18) -> 6 | X18: 46129 | Y18: =YEAR(X18) -> 2026 | Z18: =MONTH(X18) -> 4 | AA18: =DAY(X18) -> 17 | AB18: =WEEKDAY(X18) -> 6 | AC18: =EOMONTH(X18,4) -> 46265 | AD18: =NETWORKDAYS(X18,AC18) -> 97 | AP18: 16 | AQ18: Neha Kapoor | AR18: 34 | AS18: Female | AT18: Financial Analyst | AU18: 62000 | AV18: Finance | AW18: 9 | AX18: Chandigarh | BA18: 45000 | BD18: Column 1 | BE18: 10 | BF18: 795 | BG18: 79.5 | BH18: 171.16667 | BM18: ANOVA | CC18: Good | CD18: 188000 | CM18: 26-30 | CN18: 140 | CO18: 227000 | DD18: Hyderabad | DE18: 3
A19: 0 | B19: 93 | C19: Female | D19: 1 | E19: 0 | F19: 0 | G19: 3 | H19: 190.7 | I19: 114 | J19: 51 | K19: 10.91 | L19: 8.1 | M19: =SQRT(B19) -> 9.6436508 | N19: =ROUND(Table1[[#This Row],[SQRT]],2) -> 9.64 | O19: =MIN(H19,I19) -> 114 | P19: =MAX(H19,I19) -> 190.7 | Q19: =AVERAGE(H19,I19) -> 152.35 | R19: =SUM(H19,I19) -> 304.7 | S19: =MEDIAN(D19,G19) -> 2 | T19: =RANK(B19,B:B) -> #N/A | U19: =LEFT(C19,1) -> F | V19: =RIGHT(C19,2) -> le | W19: =LEN(C19) -> 6 | X19: 46130 | Y19: =YEAR(X19) -> 2026 | Z19: =MONTH(X19) -> 4 | AA19: =DAY(X19) -> 18 | AB19: =WEEKDAY(X19) -> 7 | AC19: =EOMONTH(X19,4) -> 46265 | AD19: =NETWORKDAYS(X19,AC19) -> 96 | AF19: DATE | AG19: PRODUCT | AH19: COLOR | AI19: REGION | AJ19: VALUE | AK19: TOTAL | AL19: AVG | AP19: 17 | AQ19: Ravi Teja | AR19: 22 | AS19: Male | AT19: Junior Developer | AU19: 30000 | AV19: IT | AW19: 1 | AX19: Visakhapatnam | BD19: Column 2 | BE19: 10 | BF19: 823 | BG19: 82.3 | BH19: 142.01111 | BM19: Source of Variation | BN19: SS | BO19: df | BP19: MS | BQ19: F | CC19: Grand Total | CD19: 479000 | CM19: 31-35 | CN19: 99 | CO19: 168000 | DD19: Mumbai | DE19: 2
A20: 0 | B20: 76 | C20: Male | D20: 1 | E20: 1 | F20: 2.7 | G20: 1 | H20: 189.7 | I20: 66 | J20: 78 | K20: 10.64 | L20: 10 | M20: =SQRT(B20) -> 8.7177979 | N20: =ROUND(Table1[[#This Row],[SQRT]],2) -> 8.72 | O20: =MIN(H20,I20) -> 66 | P20: =MAX(H20,I20) -> 189.7 | Q20: =AVERAGE(H20,I20) -> 127.85 | R20: =SUM(H20,I20) -> 255.7 | S20: =MEDIAN(D20,G20) -> 1 | T20: =RANK(B20,B:B) -> #N/A | U20: =LEFT(C20,1) -> M | V20: =RIGHT(C20,2) -> le | W20: =LEN(C20) -> 4 | X20: 46131 | Y20: =YEAR(X20) -> 2026 | Z20: =MONTH(X20) -> 4 | AA20: =DAY(X20) -> 19 | AB20: =WEEKDAY(X20) -> 1 | AC20: =EOMONTH(X20,4) -> 46265 | AD20: =NETWORKDAYS(X20,AC20) -> 96 | AF20: 46174 | AG20: MOUSE | AH20: RED | AI20: AP | AJ20: 100 | AK20: RED | AL20: =AVERAGEIF(AH20:AH24,"RED",AJ20:AJ24) -> 76.666667 | AP20: 18 | AQ20: Shreya Gupta | AR20: 33 | AS20: Female | AT20: Operations Manager | AU20: 70000 | AV20: Operations | AW20: 8 | AX20: Lucknow | BD20: Column 3 | BE20: 10 | BF20: 793 | BG20: 79.3 | BH20: 149.56667 | BM20: Sample | BN20: 0 | BO20: 0 | BP20: 65535 | BQ20: 65535 | CM20: Grand Total | CN20: 288 | CO20: 479000 | DD20: Grand Total | DE20: 10
AF21: 46174 | AG21: KEYBOARD | AH21: BLUE | AI21: MH | AJ21: 50 | AK21: RED+AP | AL21: =AVERAGEIFS(AJ20:AJ24,AH20:AH24,"RED",AI20:AI24,"AP") -> 76.666667 | AP21: 19 | AQ21: Suresh Babu | AR21: 41 | AS21: Male | AT21: Branch Manager | AU21: 95000 | AV21: Management | AW21: 16 | AX21: Tirupati | BM21: Columns | BN21: 45 | BO21: 1 | BP21: 45 | BQ21: 0.3086655 | BR21: Total | BS21: 4220.9667 | BT21: 29
AF22: 46175 | AG22: MOUSE | AH22: RED | AI22: AP | AJ22: 100 | AK22: RED+AP+MOUSE | AL22: =AVERAGEIFS(AJ20:AJ24,AH20:AH24,"RED",AI20:AI24,"AP",AG20:AG24,"MOUSE") -> 76.666667 | AP22: 20 | AQ22: Divya Sharma | AR22: 28 | AS22: Female | AT22: Graphic Designer | AU22: 43000 | AV22: Design | AW22: 4 | AX22: Nagpur | BM22: Interaction | BN22: 0 | BO22: 0 | BP22: 65535 | BQ22: 65535 | BR22: #NUM! | BS22: #NUM! | CM22: Row Labels | CN22: Count of ID
AF23: 46176 | AG23: MOUSE | AH23: RED | AI23: AP | AJ23: 30 | BD23: ANOVA | BM23: Within | BN23: 2624.2 | BO23: 18 | BP23: 145.78889 | CB23: Row Labels | CC23: Count of ID | CM23: Female | CN23: 5
AF24: 46177 | AG24: KEYBOARD | AH24: YELLOW | AI24: MH | AJ24: 20 | BD24: Source of Variation | BE24: SS | BF24: df | BG24: MS | BH24: F | BI24: P-value | BJ24: F crit | CB24: Finance | CC24: 2 | CM24: Male | CN24: 5
AI25: TOTAL | AJ25: =SUM(AJ20:AJ24) -> 300 | AQ25: CUSTOM FORMATTING | BD25: Between Groups | BE25: 56.266667 | BF25: 2 | BG25: 28.133333 | BH25: 0.18239009 | BI25: 0.83429436 | BJ25: 3.3541308 | BM25: Total | BN25: 2669.2 | BO25: 19 | CB25: HR | CC25: 3 | CM25: Grand Total | CN25: 10
AI26: RED | AJ26: =SUMIF(AH20:AH24,"RED",AJ20:AJ24) -> 230 | AQ26: ID | AR26: Name | AS26: Age | AT26: Subject1 Marks | AU26: Subject2 Marks | AV26: Gender | AW26: Fee | AX26: Attendance (%) | AY26: Time | AZ26: Profit | BD26: Within Groups | BE26: 4164.7 | BF26: 27 | BG26: 154.24815 | CB26: IT | CC26: 3
AI27: RED+AP | AJ27: =SUMIFS(AJ20:AJ24,AH20:AH24,"RED",AI20:AI24,"AP") -> 230 | AQ27: 1 | AR27: Rahul | AS27: 18 | AT27: 85 | AU27: 90 | AV27: Male | AW27: 15000 | AX27: 92.5 | AY27: 0.375 | AZ27: 2500 | CB27: Sales | CC27: 2
AI28: RED+AP+MOUSE | AJ28: =SUMIFS(AJ20:AJ24,AH20:AH24,"RED",AI20:AI24,"AP",AG20:AG24,"MOUSE") -> 230 | AQ28: 2 | AR28: Priya | AS28: 19 | AT28: 78 | AU28: 88 | AV28: Female | AW28: 15000 | AX28: 89 | AY28: 0.38194444 | AZ28: -500 | BD28: Total | BE28: 4220.9667 | BF28: 29 | CB28: Grand Total | CC28: 10
AQ29: 3 | AR29: Arjun | AS29: 20 | AT29: 92 | AU29: 95 | AV29: Male | AW29: 16000 | AX29: 96 | AY29: 0.37847222 | AZ29: 0
AQ30: 4 | AR30: Sneha | AS30: 18 | AT30: 81 | AU30: 84 | AV30: Female | AW30: 15000 | AX30: 91 | AY30: 0.38541667 | AZ30: 1500
AQ31: 5 | AR31: Kiran | AS31: 21 | AT31: 75 | AU31: 80 | AV31: Male | AW31: 17000 | AX31: 85.5 | AY31: 0.38888889 | AZ31: -1000 | BM31: Anova: Two-Factor Without Replication | BT31: Descriptive statistics
AQ32: 6 | AR32: Divya | AS32: 19 | AT32: 88 | AU32: 91 | AV32: Female | AW32: 16000 | AX32: 94 | AY32: 0.375 | AZ32: 3000 | BD32: Anova: Two-Factor Without Replication | BT32: Math Marks | BV32: Science Marks | BX32: English Marks
AQ33: 7 | AR33: Vikram | AS33: 20 | AT33: 67 | AU33: 72 | AV33: Male | AW33: 15500 | AX33: 82 | AY33: 0.39236111 | AZ33: 0 | BM33: SUMMARY | BN33: Count | BO33: Sum | BP33: Average | BQ33: Variance
AQ34: 8 | AR34: Anjali | AS34: 18 | AT34: 95 | AU34: 98 | AV34: Female | AW34: 16500 | AX34: 98 | AY34: 0.37152778 | AZ34: -2000 | BD34: SUMMARY | BE34: Count | BF34: Sum | BG34: Average | BH34: Variance | BM34: Row 1 | BN34: 3 | BO34: 249 | BP34: 83 | BQ34: 73 | BT34: Mean | BU34: 79.5 | BV34: Mean | BW34: 82.3 | BX34: Mean | BY34: 79.3
AF35: LOOKUP FUNCTIONS | AQ35: 9 | AR35: Rohan | AS35: 22 | AT35: 73 | AU35: 77 | AV35: Male | AW35: 17500 | AX35: 87 | AY35: 0.39583333 | AZ35: 1200 | BD35: Row 1 | BE35: 3 | BF35: 249 | BG35: 83 | BH35: 73 | BM35: Row 2 | BN35: 3 | BO35: 273 | BP35: 91 | BQ35: 13 | BT35: Standard Error | BU35: 4.1372293 | BV35: Standard Error | BW35: 3.7684362 | BX35: Standard Error | BY35: 3.867385 | CG35: Emp ID | CH35: Name | CI35: Gender | CJ35: Age | CK35: City | CL35: Department | CM35: Role | CN35: Salary | CO35: Experience (Years) | CP35: Performance | CQ35: Joining Year | CR35: Error checking | CS35: First Name | CT35: Second Name | CU35: Address
AQ36: 10 | AR36: Meena | AS36: 19 | AT36: 89 | AU36: 93 | AV36: Female | AW36: 16000 | AX36: 95 | AY36: 0.38194444 | AZ36: 0 | BD36: Row 2 | BE36: 3 | BF36: 273 | BG36: 91 | BH36: 13 | BM36: Row 3 | BN36: 3 | BO36: 223 | BP36: 74.333333 | BQ36: 86.333333 | BT36: Median | BU36: 81.5 | BV36: Median | BW36: 83 | BX36: Median | BY36: 80.5 | CF36: 0 | CG36: E007 | CH36: Sai | CI36: Male | CJ36: 23 | CK36: Chennai | CL36: IT | CM36: Developer | CN36: 42000 | CO36: 1 | CP36: Average | CQ36: 2024 | CR36: =CN36/CO36 -> 42000 | CS36: Rahul | CT36: kumar | CU36: Nandavaram(v),Banaganapalle(m),Nandyal(D)
AF37: Employee_ID | AG37: Name | AH37: Age | AI37: Gender | AJ37: Department | AK37: Job_Role | AL37: Salary | AM37: Experience_Years | AN37: Performance_Rating | AO37: Location | BD37: Row 3 | BE37: 3 | BF37: 223 | BG37: 74.333333 | BH37: 86.333333 | BM37: Row 4 | BN37: 3 | BO37: 284 | BP37: 94.666667 | BQ37: 12.333333 | BT37: Mode | BU37: #N/A | BV37: Mode | BW37: #N/A | BX37: Mode | BY37: #N/A | CF37: 0 | CG37: E001 | CH37: Rahul kumar | CI37: Male | CJ37: 24 | CK37: Hyderabad | CL37: IT | CM37: Developer | CN37: 45000 | CO37: 2 | CP37: Good | CQ37: 2023 | CR37: =CN37/CF37 -> #DIV/0! | CS37: Priya | CT37: mani | CZ37: What-If Analysis | DI37: Rahul Kumar | DJ37: Overall score | DL37: Priya Sharma | DM37: Overall score
AF38: EMP001 | AG38: Rahul Sharma | AH38: 28 | AI38: Male | AJ38: IT | AK38: Data Analyst | AL38: 55000 | AM38: 3 | AN38: 4 | AO38: Hyderabad | BD38: Row 4 | BE38: 3 | BF38: 284 | BG38: 94.666667 | BH38: 12.333333 | BM38: Row 5 | BN38: 3 | BO38: 239 | BP38: 79.666667 | BQ38: 74.333333 | BT38: Standard Deviation | BU38: 13.083068 | BV38: Standard Deviation | BW38: 11.916841 | BX38: Standard Deviation | BY38: 12.229745 | CG38: E014 | CH38: Pooja | CI38: Female | CJ38: 24 | CK38: Mumbai | CL38: HR | CM38: Recruiter | CN38: 44000 | CO38: 2 | CP38: Average | CQ38: 2023 | CR38: =CN38/CO38 -> 22000 | CZ38: Student Name | DA38: Semester 1 Marks | DB38: Semester 2 Marks | DC38: Semester 3 Marks | DD38: Semester 4 Marks | DE38: Capstone | DF38: Overall Score | DI38: Input Marks | DJ38: =DF39 -> 85 | DL38: Input Marks | DM38: =DF40 -> 90
AF39: EMP002 | AG39: Priya Reddy | AH39: 32 | AI39: Female | AJ39: HR | AK39: HR Manager | AL39: 65000 | AM39: 7 | AN39: 5 | AO39: Bangalore | AQ39: CHARTS IN EXCEL | BD39: Row 5 | BE39: 3 | BF39: 239 | BG39: 79.666667 | BH39: 74.333333 | BM39: Row 6 | BN39: 3 | BO39: 264 | BP39: 88 | BQ39: 28 | BT39: Sample Variance | BU39: 171.16667 | BV39: Sample Variance | BW39: 142.01111 | BX39: Sample Variance | BY39: 149.56667 | CG39: E011 | CH39: Rohit | CI39: Male | CJ39: 25 | CK39: Hyderabad | CL39: IT | CM39: Tester | CN39: 46000 | CO39: 2 | CP39: Average | CQ39: 2023 | CR39: =CN39/CO39 -> 23000 | CZ39: Rahul Kumar | DA39: 78 | DB39: 82 | DC39: 80 | DD39: 85 | DE39: 100 | DF39: =AVERAGE(DA39:DE39) -> 85 | DI39: 70 | DJ39: 79 | DL39: 70 | DM39: 85
AF40: EMP003 | AG40: Arjun Kumar | AH40: 26 | AI40: Male | AJ40: Sales | AK40: Sales Executive | AL40: 45000 | AM40: 2 | AN40: 3 | AO40: Chennai | BD40: Row 6 | BE40: 3 | BF40: 264 | BG40: 88 | BH40: 28 | BM40: Row 7 | BN40: 3 | BO40: 198 | BP40: 66 | BQ40: 148 | BT40: Kurtosis | BU40: -0.42524722 | BV40: Kurtosis | BW40: -0.28839458 | BX40: Kurtosis | BY40: -1.1956419 | CG40: E004 | CH40: Sneha reddy | CI40: Female | CJ40: 26 | CK40: Mumbai | CL40: IT | CM40: Tester | CN40: 48000 | CO40: 3 | CP40: Average | CQ40: 2022 | CR40: =CN40/CO40 -> 16000 | CZ40: Priya Sharma | DA40: 88 | DB40: 90 | DC40: 85 | DD40: 92 | DE40: 95 | DF40: =AVERAGE(DA40:DE40) -> 90 | DI40: 75 | DJ40: 80 | DL40: 75 | DM40: 86
...

Sheet Sheet3
A1: DATE | B1: V.TYPE | C1: V.NO | D1: STATE | E1: COURSES | F1: QUANTITY
A2: 46174 | B2: SALES | C2: LMP/35 | D2: AP | E2: PYTHON | F2: 35
B3: MPL
B4: 517326
A5: 46175 | B5: SALES | C5: LMP/36 | D5: TG | E5: PYTHON | F5: 89
B6: MPL
B7: 517326
A8: 46176 | B8: SALES | C8: LMP/37 | D8: MH | E8: PYTHON | F8: 76
B9: MPL
B10: 517326
A11: 46177 | B11: SALES | C11: LMP/38 | D11: AP | E11: PYTHON | F11: 56
A12: 46178 | B12: SALES | C12: LMP/39 | D12: AP | E12: DA | F12: 79
A13: 46179 | B13: SALES | C13: LMP/40 | D13: AP | E13: DA | F13: 60
A14: 46180 | B14: SALES | C14: LMP/41 | D14: AP | E14: DA | F14: 79
A15: 46181 | B15: SALES | C15: LMP/42 | D15: TS | E15: DA | F15: 69
A16: 46182 | B16: SALES | C16: LMP/43 | D16: TS | E16: JAVA | F16: 68
A17: 46183 | B17: SALES | C17: LMP/44 | D17: MH | E17: JAVA | F17: 90
A18: 46184 | B18: SALES | C18: LMP/45 | D18: MH | E18: JAVA | F18: 78

Sheet Sheet1
AL3: Emp ID | AM3: Name | AN3: Gender | AO3: Age | AP3: City | AQ3: Department | AR3: Role | AS3: Salary | AT3: Experience (Years) | AU3: Performance | AV3: Joining Year
AL4: E001 | AM4: Rahul | AN4: Male | AO4: 24 | AP4: Hyderabad | AQ4: IT | AR4: Developer | AS4: 45000 | AT4: 2 | AU4: Good | AV4: 2023
AL5: E002 | AM5: Priya | AN5: Female | AO5: 28 | AP5: Chennai | AQ5: HR | AR5: Recruiter | AS5: 52000 | AT5: 5 | AU5: Excellent | AV5: 2020
AL6: E003 | AM6: Arjun | AN6: Male | AO6: 31 | AP6: Bangalore | AQ6: Finance | AR6: Analyst | AS6: 60000 | AT6: 7 | AU6: Good | AV6: 2018
AL7: E004 | AM7: Sneha | AN7: Female | AO7: 26 | AP7: Mumbai | AQ7: IT | AR7: Tester | AS7: 48000 | AT7: 3 | AU7: Average | AV7: 2022
AL8: E005 | AM8: Kiran | AN8: Male | AO8: 35 | AP8: Pune | AQ8: Sales | AR8: Manager | AS8: 75000 | AT8: 10 | AU8: Excellent | AV8: 2015
AL9: E006 | AM9: Divya | AN9: Female | AO9: 29 | AP9: Hyderabad | AQ9: Marketing | AR9: Executive | AS9: 55000 | AT9: 6 | AU9: Good | AV9: 2019
AL10: E007 | AM10: Sai | AN10: Male | AO10: 23 | AP10: Chennai | AQ10: IT | AR10: Developer | AS10: 42000 | AT10: 1 | AU10: Average | AV10: 2024
AL11: E008 | AM11: Anjali | AN11: Female | AO11: 32 | AP11: Bangalore | AQ11: Finance | AR11: Manager | AS11: 78000 | AT11: 9 | AU11: Excellent | AV11: 2016
AL12: E009 | AM12: Vikas | AN12: Male | AO12: 27 | AP12: Mumbai | AQ12: HR | AR12: Executive | AS12: 50000 | AT12: 4 | AU12: Good | AV12: 2021
AL13: E010 | AM13: Kavya | AN13: Female | AO13: 30 | AP13: Pune | AQ13: Sales | AR13: Executive | AS13: 58000 | AT13: 7 | AU13: Good | AV13: 2018
AL14: E011 | AM14: Rohit | AN14: Male | AO14: 25 | AP14: Hyderabad | AQ14: IT | AR14: Tester | AS14: 46000 | AT14: 2 | AU14: Average | AV14: 2023
AL15: E012 | AM15: Meena | AN15: Female | AO15: 34 | AP15: Chennai | AQ15: Marketing | AR15: Manager | AS15: 72000 | AT15: 11 | AU15: Excellent | AV15: 2014
... AL23: E020 | AM23: Nisha | AN23: Female | AO23: 28 | AP23: Pune | AQ23: Finance | AR23: Analyst | AS23: 62000 | AT23: 6 | AU23: Excellent | AV23: 2019
AS25: =SUM(AS4:AS23) -> 1145000
AL27: Row Labels | AM27: Sum of Salary
AL28: Analyst | AM28: 187000 | AP28: Row Labels | AQ28: Sum of Experience (Years)
AL29: Developer | AM29: 185000 | AP29: Finance | AQ29: 30
AL30: Executive | AM30: 278000 | AP30: HR | AQ30: 11
AL31: Manager | AM31: 305000 | AP31: IT | AQ31: 15
AL32: Recruiter | AM32: 96000 | AP32: Marketing | AQ32: 24
AL33: Tester | AM33: 94000 | AP33: Sales | AQ33: 34
AL34: Grand Total | AM34: 1145000 | AP34: Grand Total | AQ34: 114
X48: Count of Emp ID | Y48: Column Labels
X49: Row Labels | Y49: Female | Z49: Male | AA49: Grand Total
X50: Finance | Y50: 2 | Z50: 2 | AA50: 4
X51: HR | Y51: 2 | Z51: 1 | AA51: 3
X52: IT | Y52: 2 | Z52: 4 | AA52: 6
X53: Marketing | Y53: 3 | AA53: 3 | AE53: Row Labels | AF53: Sum of Experience (Years)
X54: Sales | Y54: 1 | Z54: 3 | AA54: 4 | AE54: Average | AF54: 11
X55: Grand Total | Y55: 10 | Z55: 10 | AA55: 20 | AE55: Excellent | AF55: 61
AE56: Good | AF56: 42
AE57: Grand Total | AF57: 114

Sheet Sheet2
